Workbook

Sheet Inicio
A1: ResGes — PEDIDOS
A5: Funcionamiento: edita Proveedores y Productos. En 'Pedido' solo rellenas las cantidades; todo lo demás se actualiza solo.
A7: 1) Rellena la hoja 'Preveedores' con todos sus datos
A8: 2) Rellena la hoja 'Productos' con cada producto de cada proveedor y sus datos
A9: 3) Visualiza en la hoja de 'Pedido' los datos de cada producto, SOLO es necesario rellenar la casilla de Cantidad
A10: 4) En el apartado de totales de la hoja 'Pedido' veras el coste total del pedido
E14: Versión 2.0

Sheet Pedido
A1: PEDIDO — Rellena solo la columna 'Cantidad'; el resto se actualiza desde 'Productos'
A4: PEDIDO — Rellena solo la columna 'Cantidad'; el resto se actualiza desde 'Productos'
I5: SIN IVA | J5: IVA | K5: CON IVA
A6: Proveedor: | D6: Total por proveedor (según B5): | F6: =SUMPRODUCT(($A$9:$A$108=B6)*$I$9:$I$108) -> 0 | H6: Totales: | I6: =SUM(G9:G384) -> 1728 | J6: =SUM(H9:H384) -> 357.54 | K6: =SUM(I9:I384) -> 2085.54
A8: Proveedor (auto) | B8: Producto (auto) | C8: Unidad (auto) | D8: Precio s/IVA (auto) | E8: IVA % (auto) | F8: Cantidad | G8: Subtotal | H8: IVA € | I8: Total línea | J8: Obs. pedido | K8: Telefono
A9: =Productos!B7 -> Proveedor 1 | B9: =Productos!C7 -> Vino blanco de la casa | C9: =Productos!E7 -> Caja (6uds) | D9: =Productos!F7 -> 10 | E9: =Productos!G7 -> 21 | F9: 2 | G9: =IFERROR(D9*F9,0) -> 20 | H9: =IFERROR(G9*E9/100,0) -> 4.2 | I9: =G9+H9 -> 24.2 | K9: =IFERROR(VLOOKUP(A9,Proveedores!B7:H220,3,0), "") -> 1
A10: =Productos!B8 -> Proveedor 1 | B10: =Productos!C8 -> Vino tinto de la casa | C10: =Productos!E8 -> Caja (6uds) | D10: =Productos!F8 -> 10 | E10: =Productos!G8 -> 21 | F10: 2 | G10: =IFERROR(D10*F10,0) -> 20 | H10: =IFERROR(G10*E10/100,0) -> 4.2 | I10: =G10+H10 -> 24.2 | K10: =IFERROR(VLOOKUP(A10,Proveedores!B8:H221,3,0), "")
A11: =Productos!B9 -> Proveedor 1 | B11: =Productos!C9 -> Vino rosado de la casa | C11: =Productos!E9 -> Caja (6uds) | D11: =Productos!F9 -> 10 | E11: =Productos!G9 -> 21 | F11: 2 | G11: =IFERROR(D11*F11,0) -> 20 | H11: =IFERROR(G11*E11/100,0) -> 4.2 | I11: =G11+H11 -> 24.2 | K11: =IFERROR(VLOOKUP(A11,Proveedores!B9:H222,3,0), "")
A12: =Productos!B10 -> Proveedor 1 | B12: =Productos!C10 -> Vinagre | C12: =Productos!E10 -> Fardo (15L) | D12: =Productos!F10 -> 5 | E12: =Productos!G10 -> 10 | F12: 2 | G12: =IFERROR(D12*F12,0) -> 10 | H12: =IFERROR(G12*E12/100,0) -> 1 | I12: =G12+H12 -> 11 | K12: =IFERROR(VLOOKUP(A12,Proveedores!B10:H223,3,0), "")
A13: =Productos!B11 -> Proveedor 2 | B13: =Productos!C11 -> Servilletas de mesa | C13: =Productos!E11 -> Caja (20 paq) | D13: =Productos!F11 -> 80 | E13: =Productos!G11 -> 21 | F13: 2 | G13: =IFERROR(D13*F13,0) -> 160 | H13: =IFERROR(G13*E13/100,0) -> 33.6 | I13: =G13+H13 -> 193.6 | K13: =IFERROR(VLOOKUP(A13,Proveedores!B11:H224,3,0), "")
A14: =Productos!B12 -> Proveedor 2 | B14: =Productos!C12 -> Bayetas | C14: =Productos!E12 -> Paquete (10ud) | D14: =Productos!F12 -> 5 | E14: =Productos!G12 -> 21 | F14: 2 | G14: =IFERROR(D14*F14,0) -> 10 | H14: =IFERROR(G14*E14/100,0) -> 2.1 | I14: =G14+H14 -> 12.1 | K14: =IFERROR(VLOOKUP(A14,Proveedores!B12:H225,3,0), "")
A15: =Productos!B13 -> Proveedor 2 | B15: =Productos!C13 -> Desengrasante | C15: =Productos!E13 -> Garrafa (5L) | D15: =Productos!F13 -> 20 | E15: =Productos!G13 -> 21 | F15: 2 | G15: =IFERROR(D15*F15,0) -> 40 | H15: =IFERROR(G15*E15/100,0) -> 8.4 | I15: =G15+H15 -> 48.4 | K15: =IFERROR(VLOOKUP(A15,Proveedores!B13:H226,3,0), "")
A16: =Productos!B14 -> Proveedor 2 | B16: =Productos!C14 -> Amoniaco | C16: =Productos!E14 -> Garrafa (5L) | D16: =Productos!F14 -> 20 | E16: =Productos!G14 -> 21 | F16: 2 | G16: =IFERROR(D16*F16,0) -> 40 | H16: =IFERROR(G16*E16/100,0) -> 8.4 | I16: =G16+H16 -> 48.4 | K16: =IFERROR(VLOOKUP(A16,Proveedores!B14:H227,3,0), "")
A17: =Productos!B15 -> Proveedor 3 | B17: =Productos!C15 -> Ron barceló | C17: =Productos!E15 -> Botella | D17: =Productos!F15 -> 15 | E17: =Productos!G15 -> 21 | F17: 2 | G17: =IFERROR(D17*F17,0) -> 30 | H17: =IFERROR(G17*E17/100,0) -> 6.3 | I17: =G17+H17 -> 36.3 | K17: =IFERROR(VLOOKUP(A17,Proveedores!B15:H228,3,0), "")
A18: =Productos!B16 -> Proveedor 3 | B18: =Productos!C16 -> Gin seegrams | C18: =Productos!E16 -> Botella | D18: =Productos!F16 -> 15 | E18: =Productos!G16 -> 21 | F18: 2 | G18: =IFERROR(D18*F18,0) -> 30 | H18: =IFERROR(G18*E18/100,0) -> 6.3 | I18: =G18+H18 -> 36.3 | K18: =IFERROR(VLOOKUP(A18,Proveedores!B16:H229,3,0), "")
A19: =Productos!B17 -> Proveedor 4 | B19: =Productos!C17 -> Coca cola cristal 33cl | C19: =Productos!E17 -> Caja (24ud) | D19: =Productos!F17 -> 20 | E19: =Productos!G17 -> 21 | F19: 22 | G19: =IFERROR(D19*F19,0) -> 440 | H19: =IFERROR(G19*E19/100,0) -> 92.4 | I19: =G19+H19 -> 532.4 | K19: =IFERROR(VLOOKUP(A19,Proveedores!B17:H230,3,0), "")
A20: =Productos!B18 -> Proveedor 4 | B20: =Productos!C18 -> Coca cola zero cristal 33cl | C20: =Productos!E18 -> Caja (24ud) | D20: =Productos!F18 -> 20 | E20: =Productos!G18 -> 21 | F20: 2 | G20: =IFERROR(D20*F20,0) -> 40 | H20: =IFERROR(G20*E20/100,0) -> 8.4 | I20: =G20+H20 -> 48.4 | K20: =IFERROR(VLOOKUP(A20,Proveedores!B18:H231,3,0), "")
... A32: =Productos!B30 -> Proveedor 5 | B32: =Productos!C30 -> Barril mahou 5 estellas | C32: =Productos!E30 -> Barril 30L | D32: =Productos!F30 -> 50 | E32: =Productos!G30 -> 21 | F32: 2 | G32: =IFERROR(D32*F32,0) -> 100 | H32: =IFERROR(G32*E32/100,0) -> 21 | I32: =G32+H32 -> 121 | K32: =IFERROR(VLOOKUP(A32,Proveedores!B30:H243,3,0), "")
A33: =Productos!B31 | B33: =Productos!C31 | C33: =Productos!E31 | D33: =Productos!F31 | E33: =Productos!G31 | G33: =IFERROR(D33*F33,0) -> 0 | H33: =IFERROR(G33*E33/100,0) -> 0 | I33: =G33+H33 -> 0 | K33: =IFERROR(VLOOKUP(A33,Proveedores!B31:H244,3,0), "")
A34: =Productos!B32 | B34: =Productos!C32 | C34: =Productos!E32 | D34: =Productos!F32 | E34: =Productos!G32 | G34: =IFERROR(D34*F34,0) -> 0 | H34: =IFERROR(G34*E34/100,0) -> 0 | I34: =G34+H34 -> 0 | K34: =IFERROR(VLOOKUP(A34,Proveedores!B32:H245,3,0), "")
A35: =Productos!B33 | B35: =Productos!C33 | C35: =Productos!E33 | D35: =Productos!F33 | E35: =Productos!G33 | G35: =IFERROR(D35*F35,0) -> 0 | H35: =IFERROR(G35*E35/100,0) -> 0 | I35: =G35+H35 -> 0 | K35: =IFERROR(VLOOKUP(A35,Proveedores!B33:H246,3,0), "")
A36: =Productos!B34 | B36: =Productos!C34 | C36: =Productos!E34 | D36: =Productos!F34 | E36: =Productos!G34 | G36: =IFERROR(D36*F36,0) -> 0 | H36: =IFERROR(G36*E36/100,0) -> 0 | I36: =G36+H36 -> 0 | K36: =IFERROR(VLOOKUP(A36,Proveedores!B34:H247,3,0), "")
A37: =Productos!B35 | B37: =Productos!C35 | C37: =Productos!E35 | D37: =Productos!F35 | E37: =Productos!G35 | G37: =IFERROR(D37*F37,0) -> 0 | H37: =IFERROR(G37*E37/100,0) -> 0 | I37: =G37+H37 -> 0 | K37: =IFERROR(VLOOKUP(A37,Proveedores!B35:H248,3,0), "")
A38: =Productos!B36 | B38: =Productos!C36 | C38: =Productos!E36 | D38: =Productos!F36 | E38: =Productos!G36 | G38: =IFERROR(D38*F38,0) -> 0 | H38: =IFERROR(G38*E38/100,0) -> 0 | I38: =G38+H38 -> 0 | K38: =IFERROR(VLOOKUP(A38,Proveedores!B36:H249,3,0), "")
A39: =Productos!B37 | B39: =Productos!C37 | C39: =Productos!E37 | D39: =Productos!F37 | E39: =Productos!G37 | G39: =IFERROR(D39*F39,0) -> 0 | H39: =IFERROR(G39*E39/100,0) -> 0 | I39: =G39+H39 -> 0 | K39: =IFERROR(VLOOKUP(A39,Proveedores!B37:H250,3,0), "")
A40: =Productos!B38 | B40: =Productos!C38 | C40: =Productos!E38 | D40: =Productos!F38 | E40: =Productos!G38 | G40: =IFERROR(D40*F40,0) -> 0 | H40: =IFERROR(G40*E40/100,0) -> 0 | I40: =G40+H40 -> 0 | K40: =IFERROR(VLOOKUP(A40,Proveedores!B38:H251,3,0), "")
A41: =Productos!B39 | B41: =Productos!C39 | C41: =Productos!E39 | D41: =Productos!F39 | E41: =Productos!G39 | G41: =IFERROR(D41*F41,0) -> 0 | H41: =IFERROR(G41*E41/100,0) -> 0 | I41: =G41+H41 -> 0 | K41: =IFERROR(VLOOKUP(A41,Proveedores!B39:H252,3,0), "")
A42: =Productos!B40 | B42: =Productos!C40 | C42: =Productos!E40 | D42: =Productos!F40 | E42: =Productos!G40 | G42: =IFERROR(D42*F42,0) -> 0 | H42: =IFERROR(G42*E42/100,0) -> 0 | I42: =G42+H42 -> 0 | K42: =IFERROR(VLOOKUP(A42,Proveedores!B40:H253,3,0), "")
A43: =Productos!B41 | B43: =Productos!C41 | C43: =Productos!E41 | D43: =Productos!F41 | E43: =Productos!G41 | G43: =IFERROR(D43*F43,0) -> 0 | H43: =IFERROR(G43*E43/100,0) -> 0 | I43: =G43+H43 -> 0 | K43: =IFERROR(VLOOKUP(A43,Proveedores!B41:H254,3,0), "")
A44: =Productos!B42 | B44: =Productos!C42 | C44: =Productos!E42 | D44: =Productos!F42 | E44: =Productos!G42 | G44: =IFERROR(D44*F44,0) -> 0 | H44: =IFERROR(G44*E44/100,0) -> 0 | I44: =G44+H44 -> 0 | K44: =IFERROR(VLOOKUP(A44,Proveedores!B42:H255,3,0), "")
... A501: =Productos!B499 | B501: =Productos!C499 | C501: =Productos!E499 | D501: =Productos!F499 | E501: =Productos!G499 | G501: =IFERROR(D501*F501,0) -> 0 | H501: =IFERROR(G501*E501/100,0) -> 0 | I501: =G501+H501 -> 0 | K501: =IFERROR(VLOOKUP(A501,Proveedores!B499:H712,3,0), "")

Sheet Proveedores
A1: BASE DE DATOS DE PROVEEDORES
A4: BASE DE DATOS DE PROVEEDORES
A6: ID | B6: Nombre proveedor | C6: Persona contacto | D6: Teléfono | E6: Email | F6: Días de entrega | G6: Método de pedido | H6: Observaciones
A7: 1 | B7: Proveedor 1 | C7: Comercial 1 | D7: 1 | E7: ejemplo@ejepmlo.es | F7: Lunes, Martes, Miercoles | G7: Whatsapp
A8: 2 | B8: Proveedor 2 | C8: Comercial 2 | D8: 2 | E8: ejemplo@ejepmlo.es | F8: Lunes, Martes, Miercoles | G8: Whatsapp
A9: 3 | B9: Proveedor 3 | C9: Comercial 3 | D9: 3 | E9: ejemplo@ejepmlo.es | F9: Lunes, Martes, Miercoles | G9: Whatsapp
A10: 4 | B10: Proveedor 4 | C10: Comercial 4 | D10: 4 | E10: ejemplo@ejepmlo.es | F10: Lunes, Martes, Miercoles | G10: Whatsapp
A11: 5 | B11: Proveedor 5 | C11: Comercial 5 | D11: 5 | E11: ejemplo@ejepmlo.es | F11: Lunes, Martes, Miercoles | G11: Whatsapp
A12: 6
A13: 7
A14: 8
A15: 9
A16: 10
A17: 11
A18: 12
A19: 13
A20: 14
A21: 15
A22: 16
A23: 17
... A55: 49
A56: =A55+1 -> 50
A57: =A56+1 -> 51
A58: =A57+1 -> 52
A59: =A58+1 -> 53
A60: =A59+1 -> 54
A61: =A60+1 -> 55
A62: =A61+1 -> 56
A63: =A62+1 -> 57
A64: =A63+1 -> 58
A65: =A64+1 -> 59
A66: =A65+1 -> 60
A67: =A66+1 -> 61
... A220: =A219+1 -> 214

Sheet Productos
A1: CATÁLOGO DE PRODUCTOS (editar aquí; Pedido se actualiza solo)
A4: CATÁLOGO DE PRODUCTOS (editar aquí; Pedido se actualiza solo)
A6: ID | B6: Proveedor | C6: Nombre producto | D6: Categoría | E6: Unidad | F6: Precio unitario (€ s/IVA) | G6: IVA (%) | H6: Código proveedor | I6: Observaciones
A7: 1 | B7: Proveedor 1 | C7: Vino blanco de la casa | D7: Vino | E7: Caja (6uds) | F7: 10 | G7: 21
A8: 2 | B8: Proveedor 1 | C8: Vino tinto de la casa | D8: Vino | E8: Caja (6uds) | F8: 10 | G8: 21
A9: 3 | B9: Proveedor 1 | C9: Vino rosado de la casa | D9: Vino | E9: Caja (6uds) | F9: 10 | G9: 21
A10: 4 | B10: Proveedor 1 | C10: Vinagre | D10: Ultramarino | E10: Fardo (15L) | F10: 5 | G10: 10
A11: 5 | B11: Proveedor 2 | C11: Servilletas de mesa | D11: Limpieza | E11: Caja (20 paq) | F11: 80 | G11: 21
A12: 6 | B12: Proveedor 2 | C12: Bayetas | D12: Limpieza | E12: Paquete (10ud) | F12: 5 | G12: 21
A13: 7 | B13: Proveedor 2 | C13: Desengrasante | D13: Limpieza | E13: Garrafa (5L) | F13: 20 | G13: 21
A14: 8 | B14: Proveedor 2 | C14: Amoniaco | D14: Limpieza | E14: Garrafa (5L) | F14: 20 | G14: 21
A15: 9 | B15: Proveedor 3 | C15: Ron barceló | D15: Licor | E15: Botella | F15: 15 | G15: 21
A16: 10 | B16: Proveedor 3 | C16: Gin seegrams | D16: Licor | E16: Botella | F16: 15 | G16: 21
A17: 11 | B17: Proveedor 4 | C17: Coca cola cristal 33cl | D17: Refresco | E17: Caja (24ud) | F17: 20 | G17: 21
A18: 12 | B18: Proveedor 4 | C18: Coca cola zero cristal 33cl | D18: Refresco | E18: Caja (24ud) | F18: 20 | G18: 21
... A30: 24 | B30: Proveedor 5 | C30: Barril mahou 5 estellas | D30: Cerveza | E30: Barril 30L | F30: 50 | G30: 21
A31: 25
A32: 26
A33: 27
A34: 28
A35: 29
A36: 30
A37: 31
A38: 32
A39: 33
A40: 34
A41: 35
A42: 36
... A105: 99
A106: =A105+1 -> 100
A107: =A106+1 -> 101
A108: =A107+1 -> 102
A109: =A108+1 -> 103
A110: =A109+1 -> 104
A111: =A110+1 -> 105
A112: =A111+1 -> 106
A113: =A112+1 -> 107
A114: =A113+1 -> 108
A115: =A114+1 -> 109
A116: =A115+1 -> 110
...

Sheet BONUS Hoja de impresión Pedido
A1: Proveedor (auto) | B1: Producto (auto) | C1: Unidad (auto) | D1: Cantidad | E1: Obs. pedido
A2: =Productos!B7 -> Proveedor 1 | B2: =Productos!C7 -> Vino blanco de la casa | C2: =Productos!E7 -> Caja (6uds)
A3: =Productos!B8 -> Proveedor 1 | B3: =Productos!C8 -> Vino tinto de la casa | C3: =Productos!E8 -> Caja (6uds)
A4: =Productos!B9 -> Proveedor 1 | B4: =Productos!C9 -> Vino rosado de la casa | C4: =Productos!E9 -> Caja (6uds)
A5: =Productos!B10 -> Proveedor 1 | B5: =Productos!C10 -> Vinagre | C5: =Productos!E10 -> Fardo (15L)
A6: =Productos!B11 -> Proveedor 2 | B6: =Productos!C11 -> Servilletas de mesa | C6: =Productos!E11 -> Caja (20 paq)
A7: =Productos!B12 -> Proveedor 2 | B7: =Productos!C12 -> Bayetas | C7: =Productos!E12 -> Paquete (10ud)
A8: =Productos!B13 -> Proveedor 2 | B8: =Productos!C13 -> Desengrasante | C8: =Productos!E13 -> Garrafa (5L)
A9: =Productos!B14 -> Proveedor 2 | B9: =Productos!C14 -> Amoniaco | C9: =Productos!E14 -> Garrafa (5L)
A10: =Productos!B15 -> Proveedor 3 | B10: =Productos!C15 -> Ron barceló | C10: =Productos!E15 -> Botella
A11: =Productos!B16 -> Proveedor 3 | B11: =Productos!C16 -> Gin seegrams | C11: =Productos!E16 -> Botella
A12: =Productos!B17 -> Proveedor 4 | B12: =Productos!C17 -> Coca cola cristal 33cl | C12: =Productos!E17 -> Caja (24ud)
A13: =Productos!B18 -> Proveedor 4 | B13: =Productos!C18 -> Coca cola zero cristal 33cl | C13: =Productos!E18 -> Caja (24ud)
... A370: =Productos!B375 | B370: =Productos!C375 | C370: =Productos!E375
